<?xml version="1.0" encoding="utf-8"?>
<robot
  name="b2w_description_ros2">
  <gazebo>
    <plugin
      filename="gz-sim-odometry-publisher-system"
      name="gz::sim::systems::OdometryPublisher">
      <robot_base_frame>base_link</robot_base_frame>
      <odom_publish_frequency>100</odom_publish_frequency>
      <dimensions>3</dimensions>
      <odom_frame>odom</odom_frame>
      <tf_topic>tf</tf_topic>
    </plugin>
    <plugin
      filename="gz-sim-joint-state-publisher-system"
      name="gz::sim::systems::JointStatePublisher">
      <topic>joint_states</topic>
    </plugin>
    <plugin
      filename="gz-sim-sensors-system" name="gz::sim::systems::Sensors">
      <render_engine>ogre</render_engine>
    </plugin>
  </gazebo>
  <!-- <link name="world" />

  <joint name="world_to_base_link=" type="fixed">
      <parent link="world"/>
      <child link="base_link"/>
  </joint> -->
  <link
    name="base_link">
    <inertial>
      <origin
        xyz="0.000458 0.005261 0.000665"
        rpy="0 0 0" />
      <mass
        value="35.606" />
      <inertia
        ixx="0.27466"
        ixy="-0.000622"
        ixz="0.00315"
        iyy="1.0618"
        iyz="-0.00139"
        izz="1.1825" />
    </inertial>
    <visual>
      <origin
        xyz="0 0 0"
        rpy="0 0 0" />
      <geometry>
        <mesh
          filename="package://b2w_description_ros2/meshes/base_link.dae" />
      </geometry>
      <material
        name="">
        <color
          rgba="1 1 1 1" />
      </material>
    </visual>
    <collision>
      <origin
        xyz="0 0 0"
        rpy="0 0 0" />
        <geometry>
          <box size="0.5 0.28 0.15" />
        </geometry>
    </collision>
  </link>

  <link
    name="lidar_link">
    <inertial>
      <origin
        xyz="0.34218 0 0.17851"
        rpy="0 0 0" />
      <mass
        value="4.19E-15" />
      <inertia
        ixx="1.68E-27"
        ixy="-3.2E-45"
        ixz="7.68E-44"
        iyy="1.68E-27"
        iyz="-9.26E-47"
        izz="1.68E-27" />
    </inertial>
    <collision>
      <origin
        xyz="0 0 -0.02"
        rpy="0 0 0" />
      <geometry>
        <cylinder length="0.16" radius="0.076" />
        <!-- <mesh
          filename="package://b2_description/meshes/lidar_link.STL" /> -->
      </geometry>
    </collision>
  </link>
  <joint
    name="joint_lidar"
    type="fixed">
    <origin
      xyz="0.34218 0 0.17851"
      rpy="0 0 0" />
    <parent
      link="base_link" />
    <child
      link="lidar_link" />
    <axis
      xyz="0 0 0" />
  </joint>
  <link
    name="f_dc_link">
    <inertial>
      <origin
        xyz="3.47E-18 0 5.55E-17"
        rpy="0 0 0" />
      <mass
        value="4.19E-15" />
      <inertia
        ixx="1.68E-27"
        ixy="-9.81E-45"
        ixz="-2.54E-44"
        iyy="1.68E-27"
        iyz="0"
        izz="1.68E-27" />
    </inertial>
    <visual>
      <origin xyz="0 0 0" rpy="0 0 0"/>
      <geometry>
        <box size="0.05 0.05 0.05"/>
      </geometry>
      <material name="blue">
        <color rgba="0 0 1 1"/>
      </material>
    </visual>
  </link>
  <gazebo reference="f_dc_link">
    <sensor name="front_depth_camera" type="depth_camera">
      <camera>
        <horizontal_fov>1.93</horizontal_fov>
        <image>
          <width>64</width>
          <height>36</height>
          <format>R_FLOAT32</format>
        </image>
        <clip>
          <near>0.1</near>
          <far>4.0</far>
        </clip>
        <optical_frame_id>f_dc_link</optical_frame_id>
        <depth_camera>
          <output>depths</output>
        </depth_camera>
      </camera>
      <always_on>1</always_on>
      <update_rate>15</update_rate>
      <visualize>true</visualize>
      <topic>front_depth_camera</topic>
      <!-- <plugin
        filename="RosGzPointCloud"
        name="ros_gz_point_cloud::PointCloud">
        <topic>front_points</topic>
        <frame_id>f_dc_link</frame_id>
      </plugin> -->
    </sensor>
  </gazebo>
  <joint
    name="joint_f_dc"
    type="fixed">
    <origin
      xyz="0.42161 0.025 0.061851"
      rpy="0 0.785398 0" />
    <parent
      link="base_link" />
    <child
      link="f_dc_link" />
    <axis
      xyz="0 0 0" />
  </joint>
  <gazebo reference="joint_f_dc">
    <preserveFixedJoint>true</preserveFixedJoint>
  </gazebo>
  <link
    name="r_dc_link">
    <inertial>
      <origin
        xyz="-7.46E-16 -3.33E-16 -1.11E-15"
        rpy="0 0 0" />
      <mass
        value="4.19E-15" />
      <inertia
        ixx="1.68E-27"
        ixy="-4.31E-44"
        ixz="2.48E-45"
        iyy="1.68E-27"
        iyz="0"
        izz="1.68E-27" />
    </inertial>
    <visual>
      <origin xyz="0 0 0" rpy="0 0 0"/>
      <geometry>
        <box size="0.05 0.05 0.05"/>
      </geometry>
      <material name="blue">
        <color rgba="0 0 1 1"/>
      </material>
    </visual>
  </link>
  <gazebo reference="r_dc_link">
    <sensor name="rear_depth_camera" type="depth_camera">
      <pose>0 0 0 0 0 0</pose>
      <camera>
        <horizontal_fov>1.93</horizontal_fov>
        <image>
          <width>64</width>
          <height>36</height>
          <format>R_FLOAT32</format>
        </image>
        <clip>
          <near>0.1</near>
          <far>4.0</far>
        </clip>
        <optical_frame_id>r_dc_link</optical_frame_id>
        <depth_camera>
          <output>depths</output>
        </depth_camera>
      </camera>
      <always_on>1</always_on>
      <update_rate>15</update_rate>
      <visualize>true</visualize>
      <topic>rear_depth_camera</topic>
      <!-- <plugin
        filename="RosGzPointCloud"
        name="ros_gz_point_cloud::PointCloud">
        <topic>rear_points</topic>
        <frame_id>r_dc_link</frame_id>
      </plugin> -->
    </sensor>
  </gazebo>
  <joint
    name="joint_r_dc"
    type="fixed">
    <origin
      xyz="-0.42244 -0.025 0.038026"
      rpy="0 0.785398 3.14159" />
    <parent
      link="base_link" />
    <child
      link="r_dc_link" />
    <axis
      xyz="0 0 0" />
  </joint>
  <gazebo reference="joint_r_dc">
    <preserveFixedJoint>true</preserveFixedJoint>
  </gazebo>
  <link
    name="imu_link">
    <inertial>
      <origin
        xyz="-2.02E-17 1.73E-17 -1.39E-17"
        rpy="0 0 0" />
      <mass
        value="4.19E-15" />
      <inertia
        ixx="1.68E-27"
        ixy="1.84E-44"
        ixz="-7.35E-44"
        iyy="1.68E-27"
        iyz="-3.67E-44"
        izz="1.68E-27" />
    </inertial>
  </link>
  <joint
    name="joint_imu"
    type="fixed">
    <origin
      xyz="0 -0.02341 0.04927"
      rpy="0 0 0" />
    <parent
      link="base_link" />
    <child
      link="imu_link" />
    <axis
      xyz="0 0 0" />
  </joint>
  <link
    name="head_Link">
    <inertial>
      <origin
        xyz="0.33989 -0.000168 0.12029"
        rpy="0 0 0" />
      <mass
        value="3.6885" />
      <inertia
        ixx="0.026455"
        ixy="3.15E-05"
        ixz="0.00166"
        iyy="0.029221"
        iyz="-3.27E-05"
        izz="0.010918" />
    </inertial>
    <collision>
      <origin
        xyz="0.41 0 0.005"
        rpy="0 0 0" />
      <geometry>
        <box size="0.04 0.12 0.14" />
      </geometry>
    </collision>
  </link>
  <joint
    name="joint_head"
    type="fixed">
    <origin
      xyz="0 0 0"
      rpy="0 0 0" />
    <parent
      link="base_link" />
    <child
      link="head_Link" />
    <axis
      xyz="0 0 0" />
  </joint>
  <link
    name="tail_link">
    <inertial>
      <origin
        xyz="-0.37448 0.000488 0.006495"
        rpy="0 0 0" />
      <mass
        value="0.795" />
      <inertia
        ixx="0.0028118"
        ixy="1.95E-05"
        ixz="-7.87E-06"
        iyy="0.0047506"
        iyz="-1.57E-05"
        izz="0.0029154" />
    </inertial>
    <collision>
      <origin
        xyz="-0.405 0 0.005"
        rpy="0 0 0" />
      <geometry>
        <box size="0.025 0.12 0.14" />
      </geometry>
    </collision>
  </link>
  <joint
    name="joint_tail"
    type="fixed">
    <origin
      xyz="0 0 0"
      rpy="0 0 0" />
    <parent
      link="base_link" />
    <child
      link="tail_link" />
    <axis
      xyz="0 0 0" />
  </joint>
  <link
    name="FL_hip">
    <inertial>
      <origin
        xyz="-0.003841 -0.009068 0"
        rpy="0 0 0" />
      <mass
        value="2.673" />
      <inertia
        ixx="0.0033188"
        ixy="7.16E-05"
        ixz="-3.77E-07"
        iyy="0.0048743"
        iyz="4E-09"
        izz="0.0037087" />
    </inertial>
    <visual>
      <origin
        xyz="0 0 0"
        rpy="0 0 0" />
      <geometry>
        <mesh
          filename="package://b2w_description_ros2/meshes/FL_hip.dae" />
      </geometry>
      <material
        name="">
        <color
          rgba="1 1 1 1" />
      </material>
    </visual>
    <collision>
      <origin
        xyz="0 0.12 0"
        rpy="1.5707963267948966 0 0" />
      <geometry>
        <cylinder length="0.05" radius="0.07" />
      </geometry>
    </collision>
  </link>
  <joint
    name="FL_hip_joint"
    type="revolute">
    <origin
      xyz="0.3285 0.072 0"
      rpy="0 0 0" />
    <parent
      link="base_link" />
    <child
      link="FL_hip" />
    <axis
      xyz="1 0 0" />
    <limit
      lower="-0.87"
      upper="0.87"
      effort="200"
      velocity="23" />
    </joint>
    <gazebo>
      <plugin filename="gz-sim-joint-position-controller-system" name="gz::sim::systems::JointPositionController">
        <joint_name>FL_hip_joint</joint_name>
        <topic>FL_hip_joint_position_cmd</topic>
         <p_gain>100.0</p_gain>
        <i_gain>0.0</i_gain>
        <d_gain>3.5</d_gain>
      </plugin>
    </gazebo>
  <link
    name="FL_thigh">
    <inertial>
      <origin
        xyz="-0.006279 -0.032049 -0.057835"
        rpy="0 0 0" />
      <mass
        value="4.536" />
      <inertia
        ixx="0.062299"
        ixy="0.00087781"
        ixz="-0.0036475"
        iyy="0.061399"
        iyz="0.0083537"
        izz="0.0081997" />
    </inertial>
    <visual>
      <origin
        xyz="0 0 0"
        rpy="0 0 0" />
      <geometry>
        <mesh
          filename="package://b2w_description_ros2/meshes/FL_thigh.dae" />
      </geometry>
      <material
        name="">
        <color
          rgba="1 1 1 1" />
      </material>
    </visual>
    <collision>
      <origin rpy="0 1.57 0" xyz="-0.03 0 -0.2"/>
      <geometry>
        <box size="0.25 0.028 0.04"/>
      </geometry>
    </collision>
  </link>
  <joint
    name="FL_thigh_joint"
    type="revolute">
    <origin
      xyz="0 0.11973 0"
      rpy="0 0 0" />
    <parent
      link="FL_hip" />
    <child
      link="FL_thigh" />
    <axis
      xyz="0 1 0" />
    <limit
      lower="-0.94"
      upper="4.69"
      effort="200"
      velocity="23" />
    </joint>
    <gazebo>
      <plugin filename="gz-sim-joint-position-controller-system" name="gz::sim::systems::JointPositionController">
        <joint_name>FL_thigh_joint</joint_name>
        <topic>FL_thigh_joint_position_cmd</topic>
         <p_gain>100.0</p_gain>
        <i_gain>0.0</i_gain>
        <d_gain>3.5</d_gain>
      </plugin>
    </gazebo>
  <link
    name="FL_calf">
    <inertial>
      <origin
        xyz="0.005278 0.017301 -0.29778"
        rpy="0 0 0" />
      <mass
        value="2.2906" />
      <inertia
        ixx="0.029283"
        ixy="0.000221"
        ixz="-0.001064"
        iyy="0.030868"
        iyz="0.002093"
        izz="0.00326" />
    </inertial>
    <visual>
      <origin
        xyz="0 0 0"
        rpy="0 0 0" />
      <geometry>
        <mesh
          filename="package://b2w_description_ros2/meshes/FL_calf.dae" />
      </geometry>
      <material
        name="">
        <color
          rgba="1 1 1 1" />
      </material>
    </visual>
    <collision>
      <origin
        xyz="0 0 -0.14"
        rpy="0 0 0" />
      <geometry>
        <!-- <mesh
          filename="package://b2w_description_ros2/meshes/FL_calf.dae" /> -->
          <box size="0.03 0.028 0.27" />
      </geometry>
    </collision>
    <collision>
      <origin
        xyz="0 0.0 -0.35"
        rpy="1.5708 0 0" />
      <geometry>
        <!-- <mesh
          filename="package://b2w_description_ros2/meshes/FL_calf.dae" /> -->
          <cylinder length="0.05" radius="0.07" />
      </geometry>
    </collision>
  </link>
  <joint
    name="FL_calf_joint"
    type="revolute">
    <origin
      xyz="0 -8.8203E-05 -0.35"
      rpy="0 0 0" />
    <parent
      link="FL_thigh" />
    <child
      link="FL_calf" />
    <axis
      xyz="0 1 0" />
    <limit
      lower="-2.82"
      upper="-0.43"
      effort="320"
      velocity="14" />
    </joint>
    <gazebo>
      <plugin filename="gz-sim-joint-position-controller-system" name="gz::sim::systems::JointPositionController">
        <joint_name>FL_calf_joint</joint_name>
        <topic>FL_calf_joint_position_cmd</topic>
         <p_gain>100.0</p_gain>
        <i_gain>0.0</i_gain>
        <d_gain>3.5</d_gain>
        <!-- <initial_position>-1.3</initial_position> -->
      </plugin>
    </gazebo>
  <link
    name="FL_foot">
    <inertial>
      <origin
        xyz="-0.000991 0.051053 -0.00113"
        rpy="0 0 0" />
      <mass
        value="1.083" />
      <inertia
        ixx="0.004121"
        ixy="6E-06"
        ixz="-4.8E-05"
        iyy="0.007776"
        iyz="7E-06"
        izz="0.004108" />
    </inertial>
    <visual>
      <origin
        xyz="0 0 0"
        rpy="0 0 0" />
      <geometry>
        <mesh
          filename="package://b2w_description_ros2/meshes/FL_foot.dae" />
      </geometry>
      <material
        name="">
        <color
          rgba="1 1 1 1" />
      </material>
    </visual>
    <collision>
      <origin
        xyz="0 0.04 0"
        rpy="1.5708 0 0" />
      <geometry>
        <!-- <mesh
          filename="package://b2w_description_ros2/meshes/FL_foot.dae" /> -->
          <cylinder length="0.02" radius="0.1125" />
      </geometry>
    </collision>
  </link>
  <joint
    name="FL_foot_joint"
    type="continuous">
    <origin
      xyz="0 0 -0.35"
      rpy="0 0 0" />
    <parent
      link="FL_calf" />
    <child
      link="FL_foot" />
    <axis
      xyz="0 1 0" />
    <limit
      effort="20"
      velocity="50" />
    </joint>
    <gazebo>
      <plugin filename="gz-sim-joint-controller-system" name="gz::sim::systems::JointController">
        <joint_name>FL_foot_joint</joint_name>
        <topic>FL_foot_joint_velocity_cmd</topic>
        <p_gain>0.0</p_gain>
        <i_gain>0.0</i_gain>
        <d_gain>3.0</d_gain>
      </plugin>
    </gazebo>
    <link
    name="FR_hip">
    <inertial>
      <origin
        xyz="-0.003841 0.009068 0"
        rpy="0 0 0" />
      <mass
        value="2.673" />
      <inertia
        ixx="0.003318772"
        ixy="-7.16E-05"
        ixz="-3.77E-07"
        iyy="0.004874327"
        iyz="-4E-09"
        izz="0.003708731" />
    </inertial>
    <visual>
      <origin
        xyz="0 0 0"
        rpy="0 0 0" />
      <geometry>
        <mesh
          filename="package://b2w_description_ros2/meshes/FR_hip.dae" />
      </geometry>
      <material
        name="">
        <color
          rgba="1 1 1 1" />
      </material>
    </visual>
    <collision>
      <origin
        xyz="0 -0.12 0"
        rpy="1.5707963267948966 0 0" />
      <geometry>
        <cylinder length="0.05" radius="0.07" />
      </geometry>
    </collision>
  </link>
  <joint
    name="FR_hip_joint"
    type="revolute">
    <origin
      xyz="0.3285 -0.072 0"
      rpy="0 0 0" />
    <parent
      link="base_link" />
    <child
      link="FR_hip" />
    <axis
      xyz="1 0 0" />
    <limit
      lower="-0.87"
      upper="0.87"
      effort="200"
      velocity="23" />
    </joint>
    <gazebo>
      <plugin filename="gz-sim-joint-position-controller-system" name="gz::sim::systems::JointPositionController">
        <joint_name>FR_hip_joint</joint_name>
        <topic>FR_hip_joint_position_cmd</topic>
         <p_gain>100.0</p_gain>
        <i_gain>0.0</i_gain>
        <d_gain>3.5</d_gain>
      </plugin>
    </gazebo>
  <link
    name="FR_thigh">
    <inertial>
      <origin
        xyz="-0.006279 0.032049 -0.057835"
        rpy="0 0 0" />
      <mass
        value="4.536" />
      <inertia
        ixx="0.06229908"
        ixy="-0.000877808"
        ixz="-0.003647464"
        iyy="0.06139927"
        iyz="-0.008353671"
        izz="0.008199745" />
    </inertial>
    <visual>
      <origin
        xyz="0 0 0"
        rpy="0 0 0" />
      <geometry>
        <mesh
          filename="package://b2w_description_ros2/meshes/FR_thigh.dae" />
      </geometry>
      <material
        name="">
        <color
          rgba="1 1 1 1" />
      </material>
    </visual>
    <collision>
      <origin rpy="0 1.57 0" xyz="-0.03 0 -0.2"/>
      <geometry>
        <box size="0.25 0.028 0.04"/>
      </geometry>
    </collision>
  </link>
  <joint
    name="FR_thigh_joint"
    type="revolute">
    <origin
      xyz="0 -0.11973 0"
      rpy="0 0 0" />
    <parent
      link="FR_hip" />
    <child
      link="FR_thigh" />
    <axis
      xyz="0 1 0" />
    <limit
      lower="-0.94"
      upper="4.69"
      effort="200"
      velocity="23" />
    </joint>
    <gazebo>
      <plugin filename="gz-sim-joint-position-controller-system" name="gz::sim::systems::JointPositionController">
        <joint_name>FR_thigh_joint</joint_name>
        <topic>FR_thigh_joint_position_cmd</topic>
         <p_gain>100.0</p_gain>
        <i_gain>0.0</i_gain>
        <d_gain>3.5</d_gain>
      </plugin>
    </gazebo>
  <link
    name="FR_calf">
    <inertial>
      <origin
        xyz="0.005278 -0.017301 -0.297775"
        rpy="0 0 0" />
      <mass
        value="2.290557" />
      <inertia
        ixx="0.029283"
        ixy="-0.000221"
        ixz="-0.001064"
        iyy="0.030868"
        iyz="-0.002093"
        izz="0.00326" />
    </inertial>
    <visual>
      <origin
        xyz="0 0 0"
        rpy="0 0 0" />
      <geometry>
        <mesh
          filename="package://b2w_description_ros2/meshes/FR_calf.dae" />
      </geometry>
      <material
        name="">
        <color
          rgba="1 1 1 1" />
      </material>
    </visual>
    <collision>
      <origin
        xyz="0 0 -0.14"
        rpy="0 0 0" />
      <geometry>
        <!-- <mesh
          filename="package://b2w_description_ros2/meshes/FR_calf.dae" /> -->
          <box size="0.03 0.028 0.27" />
      </geometry>
    </collision>
    <collision>
      <origin
        xyz="0 0.0 -0.35"
        rpy="1.5708 0 0" />
      <geometry>
        <!-- <mesh
          filename="package://b2w_description_ros2/meshes/FL_calf.dae" /> -->
          <cylinder length="0.05" radius="0.07" />
      </geometry>
    </collision>
  </link>
  <joint
    name="FR_calf_joint"
    type="revolute">
    <origin
      xyz="0 8.8205E-05 -0.35"
      rpy="0 0 0" />
    <parent
      link="FR_thigh" />
    <child
      link="FR_calf" />
    <axis
      xyz="0 1 0" />
    <limit
      lower="-2.82"
      upper="-0.43"
      effort="320"
      velocity="14" />
    </joint>
    <gazebo>
      <plugin filename="gz-sim-joint-position-controller-system" name="gz::sim::systems::JointPositionController">
        <joint_name>FR_calf_joint</joint_name>
        <topic>FR_calf_joint_position_cmd</topic>
         <p_gain>100.0</p_gain>
        <i_gain>0.0</i_gain>
        <d_gain>3.5</d_gain>
        <!-- <initial_position>-1.3</initial_position> -->
      </plugin>
    </gazebo>
  <link
    name="FR_foot">
    <inertial>
      <origin
        xyz="-0.000991 -0.051053 -0.00113"
        rpy="0 0 0" />
      <mass
        value="1.083" />
      <inertia
        ixx="0.004121"
        ixy="-6E-06"
        ixz="-4.8E-05"
        iyy="0.007776"
        iyz="-7E-06"
        izz="0.004108" />
    </inertial>
    <visual>
      <origin
        xyz="0 0 0"
        rpy="0 0 0" />
      <geometry>
        <mesh
          filename="package://b2w_description_ros2/meshes/FR_foot.dae" />
      </geometry>
      <material
        name="">
        <color
          rgba="1 1 1 1" />
      </material>
    </visual>
    <collision>
      <origin
        xyz="0 -0.04 0"
        rpy="1.5708 0 0" />
      <geometry>
        <!-- <mesh
          filename="package://b2w_description_ros2/meshes/FR_foot.dae" /> -->
          <cylinder length="0.02" radius="0.1125" />
      </geometry>
    </collision>
  </link>
  <joint
    name="FR_foot_joint"
    type="continuous">
    <origin
      xyz="0 -0.001 -0.35"
      rpy="0 0 0" />
    <parent
      link="FR_calf" />
    <child
      link="FR_foot" />
    <axis
      xyz="0 1 0" />
    <limit
      effort="20"
      velocity="50" />
    </joint>
    <gazebo>
      <plugin filename="gz-sim-joint-controller-system" name="gz::sim::systems::JointController">
        <joint_name>FR_foot_joint</joint_name>
        <topic>FR_foot_joint_velocity_cmd</topic>
        <p_gain>0.0</p_gain>
        <i_gain>0.0</i_gain>
        <d_gain>3.0</d_gain>
      </plugin>
    </gazebo>
  <link
    name="RL_hip">
    <inertial>
      <origin
        xyz="0.003841 -0.009068 0"
        rpy="0 0 0" />
      <mass
        value="2.673" />
      <inertia
        ixx="0.0033188"
        ixy="-7.16E-05"
        ixz="3.77E-07"
        iyy="0.0048743"
        iyz="4E-09"
        izz="0.0037087" />
    </inertial>
    <visual>
      <origin
        xyz="0 0 0"
        rpy="0 0 0" />
      <geometry>
        <mesh
          filename="package://b2w_description_ros2/meshes/RL_hip.dae" />
      </geometry>
      <material
        name="">
        <color
          rgba="1 1 1 1" />
      </material>
    </visual>
    <collision>
      <origin
        xyz="0 0.12 0"
        rpy="1.5707963267948966 0 0" />
      <geometry>
        <cylinder length="0.05" radius="0.07" />
      </geometry>
    </collision>
  </link>
  <joint
    name="RL_hip_joint"
    type="revolute">
    <origin
      xyz="-0.3285 0.072 0"
      rpy="0 0 0" />
    <parent
      link="base_link" />
    <child
      link="RL_hip" />
    <axis
      xyz="1 0 0" />
    <limit
      lower="-0.87"
      upper="0.87"
      effort="200"
      velocity="23" />
    </joint>
    <gazebo>
      <plugin filename="gz-sim-joint-position-controller-system" name="gz::sim::systems::JointPositionController">
        <joint_name>RL_hip_joint</joint_name>
        <topic>RL_hip_joint_position_cmd</topic>
         <p_gain>100.0</p_gain>
        <i_gain>0.0</i_gain>
        <d_gain>3.5</d_gain>
      </plugin>
    </gazebo>
  <link
    name="RL_thigh">
    <inertial>
      <origin
        xyz="-0.006279 -0.032049 -0.057835"
        rpy="0 0 0" />
      <mass
        value="4.536" />
      <inertia
        ixx="0.06229908"
        ixy="-0.000877808"
        ixz="-0.003647464"
        iyy="0.06139927"
        iyz="0.008353671"
        izz="0.008199745" />
    </inertial>
    <visual>
      <origin
        xyz="0 0 0"
        rpy="0 0 0" />
      <geometry>
        <mesh
          filename="package://b2w_description_ros2/meshes/RL_thigh.dae" />
      </geometry>
      <material
        name="">
        <color
          rgba="1 1 1 1" />
      </material>
    </visual>
    <collision>
      <origin rpy="0 1.57 0" xyz="-0.03 0 -0.2"/>
      <geometry>
        <box size="0.25 0.028 0.04"/>
      </geometry>
    </collision>
  </link>
  <joint
    name="RL_thigh_joint"
    type="revolute">
    <origin
      xyz="0 0.11973 0"
      rpy="0 0 0" />
    <parent
      link="RL_hip" />
    <child
      link="RL_thigh" />
    <axis
      xyz="0 1 0" />
    <limit
      lower="-0.94"
      upper="4.69"
      effort="200"
      velocity="23" />
    </joint>
    <gazebo>
      <plugin filename="gz-sim-joint-position-controller-system" name="gz::sim::systems::JointPositionController">
        <joint_name>RL_thigh_joint</joint_name>
        <topic>RL_thigh_joint_position_cmd</topic>
         <p_gain>100.0</p_gain>
        <i_gain>0.0</i_gain>
        <d_gain>3.5</d_gain>
      </plugin>
    </gazebo>
  <link
    name="RL_calf">
    <inertial>
      <origin
        xyz="0.005278 0.017301 -0.29778"
        rpy="0 0 0" />
      <mass
        value="2.2906" />
      <inertia
        ixx="0.029283"
        ixy="0.000221"
        ixz="-0.001064"
        iyy="0.030868"
        iyz="0.002093"
        izz="0.00326" />
    </inertial>
    <visual>
      <origin
        xyz="0 0 0"
        rpy="0 0 0" />
      <geometry>
        <mesh
          filename="package://b2w_description_ros2/meshes/RL_calf.dae" />
      </geometry>
      <material
        name="">
        <color
          rgba="1 1 1 1" />
      </material>
    </visual>
    <collision>
      <origin
        xyz="0 0 -0.14"
        rpy="0 0 0" />
      <geometry>
        <!-- <mesh
          filename="package://b2w_description_ros2/meshes/RL_calf.dae" /> -->
          <box size="0.03 0.028 0.27" />
      </geometry>
    </collision>
    <collision>
      <origin
        xyz="0 0.0 -0.35"
        rpy="1.5708 0 0" />
      <geometry>
        <!-- <mesh
          filename="package://b2w_description_ros2/meshes/FL_calf.dae" /> -->
          <cylinder length="0.05" radius="0.07" />
      </geometry>
    </collision>
  </link>
  <joint
    name="RL_calf_joint"
    type="revolute">
    <origin
      xyz="0 -8.8205E-05 -0.35"
      rpy="0 0 0" />
    <parent
      link="RL_thigh" />
    <child
      link="RL_calf" />
    <axis
      xyz="0 1 0" />
    <limit
      lower="-2.82"
      upper="-0.43"
      effort="320"
      velocity="14" />
    </joint>
    <gazebo>
      <plugin filename="gz-sim-joint-position-controller-system" name="gz::sim::systems::JointPositionController">
        <joint_name>RL_calf_joint</joint_name>
        <topic>RL_calf_joint_position_cmd</topic>
         <p_gain>100.0</p_gain>
        <i_gain>0.0</i_gain>
        <d_gain>3.5</d_gain>
        <!-- <initial_position>-1.3</initial_position> -->
      </plugin>
    </gazebo>
  <link
    name="RL_foot">
    <inertial>
      <origin
        xyz="-0.000991 0.051053 -0.00113"
        rpy="0 0 0" />
      <mass
        value="1.083" />
      <inertia
        ixx="0.004121"
        ixy="-6E-06"
        ixz="-4.8E-05"
        iyy="0.007776"
        iyz="-7E-06"
        izz="0.004108" />
    </inertial>
    <visual>
      <origin
        xyz="0 0 0"
        rpy="0 0 0" />
      <geometry>
        <mesh
          filename="package://b2w_description_ros2/meshes/RL_foot.dae" />
      </geometry>
      <material
        name="">
        <color
          rgba="1 1 1 1" />
      </material>
    </visual>
    <collision>
      <origin
        xyz="0 0.04 0"
        rpy="1.5708 0 0" />
      <geometry>
        <!-- <mesh
          filename="package://b2w_description_ros2/meshes/RL_foot.dae" /> -->
          <cylinder length="0.02" radius="0.1125" />
      </geometry>
    </collision>
  </link>
  <joint
    name="RL_foot_joint"
    type="continuous">
    <origin
      xyz="0 0 -0.35"
      rpy="0 0 0" />
    <parent
      link="RL_calf" />
    <child
      link="RL_foot" />
    <axis
      xyz="0 1 0" />
    <limit
      effort="20"
      velocity="50" />
    </joint>
    <gazebo>
      <plugin filename="gz-sim-joint-controller-system" name="gz::sim::systems::JointController">
        <joint_name>RL_foot_joint</joint_name>
        <topic>RL_foot_joint_velocity_cmd</topic>
        <p_gain>0.0</p_gain>
        <i_gain>0.0</i_gain>
        <d_gain>3.0</d_gain>
      </plugin>
    </gazebo>
  <link
    name="RR_hip">
    <inertial>
      <origin
        xyz="0.003841 0.009068 0"
        rpy="0 0 0" />
      <mass
        value="2.673" />
      <inertia
        ixx="0.0033188"
        ixy="7.16E-05"
        ixz="3.77E-07"
        iyy="0.0048743"
        iyz="-4E-09"
        izz="0.0037087" />
    </inertial>
    <visual>
      <origin
        xyz="0 0 0"
        rpy="0 0 0" />
      <geometry>
        <mesh
          filename="package://b2w_description_ros2/meshes/RR_hip.dae" />
      </geometry>
      <material
        name="">
        <color
          rgba="1 1 1 1" />
      </material>
    </visual>
    <collision>
      <origin
        xyz="0 -0.12 0"
        rpy="1.5707963267948966 0 0" />
      <geometry>
        <cylinder length="0.05" radius="0.07" />
      </geometry>
    </collision>
  </link>
  <joint
    name="RR_hip_joint"
    type="revolute">
    <origin
      xyz="-0.3285 -0.072 0"
      rpy="0 0 0" />
    <parent
      link="base_link" />
    <child
      link="RR_hip" />
    <axis
      xyz="1 0 0" />
    <limit
      lower="-0.87"
      upper="0.87"
      effort="200"
      velocity="23" />
    </joint>
    <gazebo>
      <plugin filename="gz-sim-joint-position-controller-system" name="gz::sim::systems::JointPositionController">
        <joint_name>RR_hip_joint</joint_name>
        <topic>RR_hip_joint_position_cmd</topic>
         <p_gain>100.0</p_gain>
        <i_gain>0.0</i_gain>
        <d_gain>3.5</d_gain>
      </plugin>
    </gazebo>
  <link
    name="RR_thigh">
    <inertial>
      <origin
        xyz="-0.006279 0.032049 -0.057835"
        rpy="0 0 0" />
      <mass
        value="4.536" />
      <inertia
        ixx="0.062299"
        ixy="-0.00087781"
        ixz="-0.0036475"
        iyy="0.061399"
        iyz="-0.0083537"
        izz="0.0081997" />
    </inertial>
    <visual>
      <origin
        xyz="0 0 0"
        rpy="0 0 0" />
      <geometry>
        <mesh
          filename="package://b2w_description_ros2/meshes/RR_thigh.dae" />
      </geometry>
      <material
        name="">
        <color
          rgba="1 1 1 1" />
      </material>
    </visual>
    <collision>
      <origin rpy="0 1.57 0" xyz="-0.03 0 -0.2"/>
      <geometry>
        <box size="0.25 0.028 0.04"/>
      </geometry>
    </collision>
  </link>
  <joint
    name="RR_thigh_joint"
    type="revolute">
    <origin
      xyz="0 -0.11973 0"
      rpy="0 0 0" />
    <parent
      link="RR_hip" />
    <child
      link="RR_thigh" />
    <axis
      xyz="0 1 0" />
    <limit
      lower="-0.94"
      upper="4.69"
      effort="200"
      velocity="23" />
    </joint>
    <gazebo>
      <plugin filename="gz-sim-joint-position-controller-system" name="gz::sim::systems::JointPositionController">
        <joint_name>RR_thigh_joint</joint_name>
        <topic>RR_thigh_joint_position_cmd</topic>
         <p_gain>100.0</p_gain>
        <i_gain>0.0</i_gain>
        <d_gain>3.5</d_gain>
      </plugin>
    </gazebo>
  <link
    name="RR_calf">
    <inertial>
      <origin
        xyz="0.005278 -0.017301 -0.29778"
        rpy="0 0 0" />
      <mass
        value="2.2906" />
      <inertia
        ixx="0.029283"
        ixy="-0.000221"
        ixz="-0.001064"
        iyy="0.030868"
        iyz="-0.002093"
        izz="0.00326" />
    </inertial>
    <visual>
      <origin
        xyz="0 0 0"
        rpy="0 0 0" />
      <geometry>
        <mesh
          filename="package://b2w_description_ros2/meshes/RR_calf.dae" />
      </geometry>
      <material
        name="">
        <color
          rgba="1 1 1 1" />
      </material>
    </visual>
    <collision>
      <origin
        xyz="0 0 -0.14"
        rpy="0 0 0" />
      <geometry>
        <!-- <mesh
          filename="package://b2w_description_ros2/meshes/RR_calf.dae" /> -->
          <box size="0.03 0.028 0.27" />
      </geometry>
    </collision>
    <collision>
      <origin
        xyz="0 0.0 -0.35"
        rpy="1.5708 0 0" />
      <geometry>
        <!-- <mesh
          filename="package://b2w_description_ros2/meshes/FL_calf.dae" /> -->
          <cylinder length="0.05" radius="0.07" />
      </geometry>
    </collision>
  </link>
  <joint
    name="RR_calf_joint"
    type="revolute">
    <origin
      xyz="0 8.8205E-05 -0.35"
      rpy="0 0 0" />
    <parent
      link="RR_thigh" />
    <child
      link="RR_calf" />
    <axis
      xyz="0 1 0" />
    <limit
      lower="-2.82"
      upper="-0.43"
      effort="320"
      velocity="14" />
    </joint>
    <gazebo>
      <plugin filename="gz-sim-joint-position-controller-system" name="gz::sim::systems::JointPositionController">
        <joint_name>RR_calf_joint</joint_name>
        <topic>RR_calf_joint_position_cmd</topic>
         <p_gain>100.0</p_gain>
        <i_gain>0.0</i_gain>
        <d_gain>3.5</d_gain>
        <!-- <initial_position>-1.3</initial_position> -->
      </plugin>
    </gazebo>
  <link
    name="RR_foot">
    <inertial>
      <origin
        xyz="-0.000991 -0.051053 -0.00113"
        rpy="0 0 0" />
      <mass
        value="1.083" />
      <inertia
        ixx="0.004121"
        ixy="-6E-06"
        ixz="-4.8E-05"
        iyy="0.007776"
        iyz="-7E-06"
        izz="0.004108" />
    </inertial>
    <visual>
      <origin
        xyz="0 0 0"
        rpy="0 0 0" />
      <geometry>
        <mesh
          filename="package://b2w_description_ros2/meshes/RR_foot.dae" />
      </geometry>
      <material
        name="">
        <color
          rgba="1 1 1 1" />
      </material>
    </visual>
    <collision>
      <origin
        xyz="0 -0.04 0"
        rpy="1.5708 0 0" />
      <geometry>
        <!-- <mesh
          filename="package://b2w_description_ros2/meshes/RR_foot.dae" /> -->
          <cylinder length="0.02" radius="0.1125" />
      </geometry>
    </collision>
  </link>
  <joint
    name="RR_foot_joint"
    type="continuous">
    <origin
      xyz="0 -0.001 -0.35"
      rpy="0 0 0" />
    <parent
      link="RR_calf" />
    <child
      link="RR_foot" />
    <axis
      xyz="0 1 0" />
    <limit
      effort="20"
      velocity="50" />
    </joint>
    <gazebo>
      <plugin filename="gz-sim-joint-controller-system" name="gz::sim::systems::JointController">
        <joint_name>RR_foot_joint</joint_name>
        <topic>RR_foot_joint_velocity_cmd</topic>
        <p_gain>0.0</p_gain>
        <i_gain>0.0</i_gain>
        <d_gain>3.0</d_gain>
      </plugin>
    </gazebo>
  <link
    name="f_oc_link">
    <inertial>
      <origin
        xyz="-3.39E-15 1.46E-16 -6.11E-16"
        rpy="0 0 0" />
      <mass
        value="4.19E-15" />
      <inertia
        ixx="1.68E-27"
        ixy="-3.89E-44"
        ixz="5.04E-44"
        iyy="1.68E-27"
        iyz="2.81E-45"
        izz="1.68E-27" />
    </inertial>
  </link>
  <joint
    name="f_oc_joint"
    type="fixed">
    <origin
      xyz="0.3993 0 -0.01576"
      rpy="-1.5708 0 -1.5708" />
    <parent
      link="base_link" />
    <child
      link="f_oc_link" />
    <axis
      xyz="0 0 0" />
  </joint>
  <link
    name="logo_link">
    <inertial>
      <origin
        xyz="0 -2.3E-23 0"
        rpy="0 0 0" />
      <mass
        value="4.19E-15" />
      <inertia
        ixx="1.68E-27"
        ixy="0"
        ixz="0"
        iyy="1.68E-27"
        iyz="0"
        izz="1.68E-27" />
    </inertial>
  </link>
  <joint
    name="joint_logo"
    type="fixed">
    <origin
      xyz="0 0 0"
      rpy="0 0 0" />
    <parent
      link="base_link" />
    <child
      link="logo_link" />
    <axis
      xyz="0 0 0" />
  </joint>
  <link
    name="r_oc_ink">
    <inertial>
      <origin
        xyz="-0.39143 1.52E-07 -0.011961"
        rpy="0 0 0" />
      <mass
        value="4.19E-12" />
      <inertia
        ixx="1.68E-22"
        ixy="9.03E-39"
        ixz="0"
        iyy="1.68E-22"
        iyz="-1.2E-38"
        izz="1.68E-22" />
    </inertial>
  </link>
  <joint
    name="joint_r_oc"
    type="fixed">
    <origin
      xyz="-0.39143 0 -0.026131"
      rpy="-1.5708 0 1.5708" />
    <parent
      link="base_link" />
    <child
      link="r_oc_ink" />
    <axis
      xyz="0 0 0" />
  </joint>

  <!-- Depth Camera Link -->
  <link name="zed_x_camera">
    <!-- <visual>
      <origin xyz="0 0 0" rpy="0 0 0"/>
      <geometry>
        <box size="0.05 0.1 0.01"/>
      </geometry>
    </visual> -->
    <collision>
      <origin xyz="0 0 0" rpy="0 0 0"/>
      <geometry>
        <box size="0.05 0.1 0.01"/>
      </geometry>
    </collision>
    <inertial>
      <origin xyz="0 0 0" rpy="0 0 0"/>
      <mass value="0.01"/>
      <inertia ixx="0.01" ixy="0" ixz="0" iyy="0.01" iyz="0" izz="0.01"/>
    </inertial>
  </link>

  <!-- Joint connecting depth camera to base -->
  <joint name="base_to_zed_x_camera" type="fixed">
    <parent link="base_link"/>
    <child link="zed_x_camera"/>
    <origin xyz="0.4 0.0 0.5" rpy="0 0.349066 0"/>
  </joint>

  <gazebo reference="base_to_zed_x_camera">
    <preserveFixedJoint>true</preserveFixedJoint>
  </gazebo>

  <!-- Collision Plate Link -->
  <link name="collision_plate">
    <visual>
      <origin xyz="0 0 0" rpy="0 0 0"/>
      <geometry>
        <box size="0.85 0.45 0.02"/>
      </geometry>
      <material name="collision_plate_material">
        <color rgba="0.8 0.8 0.8 0.5"/>
      </material>
    </visual>
    <collision>
      <origin xyz="0 0 0" rpy="0 0 0"/>
      <geometry>
        <box size="0.95 0.45 0.02"/>
      </geometry>
    </collision>
    <inertial>
      <origin xyz="0 0 0" rpy="0 0 0"/>
      <mass value="0.1"/>
      <inertia ixx="0.0014" ixy="0" ixz="0" iyy="0.003" iyz="0" izz="0.004"/>
    </inertial>
  </link>

  <!-- Joint connecting collision plate to base -->
  <joint name="base_to_collision_plate" type="fixed">
    <parent link="base_link"/>
    <child link="collision_plate"/>
    <origin xyz="0.0 0.0 0.1" rpy="0 0 0"/>
  </joint>

  <gazebo reference="base_to_collision_plate">
    <preserveFixedJoint>true</preserveFixedJoint>
  </gazebo>

  <!-- Force-Torque Sensor for Collision Plate -->
  <gazebo reference="base_to_collision_plate">
    <sensor name="force_torque" type="force_torque">
      <always_on>true</always_on>
      <update_rate>100.0</update_rate>
      <visualize>true</visualize>
      <topic>collision_plate/force_torque</topic>
      <force_torque>
        <frame>child</frame>
        <measure_direction>child_to_parent</measure_direction>
      </force_torque>
      <plugin
        filename="gz-sim-forcetorque-system"
        name="gz::sim::systems::ForceTorque">
      </plugin>
    </sensor>
  </gazebo>

  <gazebo reference="zed_x_camera">
    <sensor name="zed_x_camera" type="depth_camera">
      <!-- alive & ticking at 15 Hz -->
      <always_on>1</always_on>
      <update_rate>15</update_rate>
      <visualize>true</visualize>
      <topic>zed_x_camera</topic>

      <camera>
        <!-- recomputed from fx=90.8774 @ 240px -->
        <horizontal_fov>1.845264</horizontal_fov>

        <image>
          <width>240</width>
          <height>150</height>
          <format>R_FLOAT32</format>
        </image>

        <!-- ZED X ideal depth range -->
        <clip>
          <near>0.3</near>
          <far>20.0</far>
        </clip>

        <lens>
          <type>pinhole</type>
          <intrinsics>
            <!-- direct from your CameraInfo -->
            <fx>90.87739562988281</fx>
            <fy>90.87739562988281</fy>
            <cx>117.93769836425781</cx>
            <cy>78.08038330078125</cy>
            <s>0.0</s>
          </intrinsics>
        </lens>

        <distortion>
          <!-- your d[] were all zero -->
          <k1>0.0</k1>
          <k2>0.0</k2>
          <k3>0.0</k3>
          <p1>0.0</p1>
          <p2>0.0</p2>
          <center>117.93769836425781 78.08038330078125</center>
        </distortion>

        <optical_frame_id>zed_x_camera</optical_frame_id>

        <depth_camera>
          <output>depths</output>
          <clip>
            <near>0.3</near>
            <far>20.0</far>
          </clip>
        </depth_camera>
      </camera>
    </sensor>
  </gazebo>

</robot>
